Traceback (most recent call last):
  File "/home/wsaelens/projects/probabilistic-cell/.venv/lib/python3.8/site-packages/jupyter_cache/executors/utils.py", line 51, in single_nb_execution
    executenb(
  File "/home/wsaelens/projects/probabilistic-cell/.venv/lib/python3.8/site-packages/nbclient/client.py", line 1117, in execute
    return NotebookClient(nb=nb, resources=resources, km=km, **kwargs).execute()
  File "/home/wsaelens/projects/probabilistic-cell/.venv/lib/python3.8/site-packages/nbclient/util.py", line 78, in wrapped
    return just_run(coro(*args, **kwargs))
  File "/home/wsaelens/projects/probabilistic-cell/.venv/lib/python3.8/site-packages/nbclient/util.py", line 57, in just_run
    return loop.run_until_complete(coro)
  File "/usr/lib/python3.8/asyncio/base_events.py", line 616, in run_until_complete
    return future.result()
  File "/home/wsaelens/projects/probabilistic-cell/.venv/lib/python3.8/site-packages/nbclient/client.py", line 558, in async_execute
    await self.async_execute_cell(
  File "/home/wsaelens/projects/probabilistic-cell/.venv/lib/python3.8/site-packages/nbclient/client.py", line 862, in async_execute_cell
    self._check_raise_for_error(cell, exec_reply)
  File "/home/wsaelens/projects/probabilistic-cell/.venv/lib/python3.8/site-packages/nbclient/client.py", line 765, in _check_raise_for_error
    raise CellExecutionError.from_cell_and_msg(cell, exec_reply_content)
nbclient.exceptions.CellExecutionError: An error occurred while executing the following cell:
------------------
from myst_nb import glue
logistic = la.links.scalar.Logistic._repr_formula_latex_()
glue("logistic", logistic, display=False)

spline = la.links.scalar.Spline._repr_formula_latex_()
glue("spline", logistic, display=False)

sigmoid = la.links.scalar.Sigmoid._repr_formula_latex_()
glue("sigmoid", logistic, display=False)
------------------

[0;31m---------------------------------------------------------------------------[0m
[0;31mTypeError[0m                                 Traceback (most recent call last)
[0;32m/tmp/ipykernel_2650336/261086097.py[0m in [0;36m<module>[0;34m[0m
[1;32m      3[0m [0mglue[0m[0;34m([0m[0;34m"logistic"[0m[0;34m,[0m [0mlogistic[0m[0;34m,[0m [0mdisplay[0m[0;34m=[0m[0;32mFalse[0m[0;34m)[0m[0;34m[0m[0;34m[0m[0m
[1;32m      4[0m [0;34m[0m[0m
[0;32m----> 5[0;31m [0mspline[0m [0;34m=[0m [0mla[0m[0;34m.[0m[0mlinks[0m[0;34m.[0m[0mscalar[0m[0;34m.[0m[0mSpline[0m[0;34m.[0m[0m_repr_formula_latex_[0m[0;34m([0m[0;34m)[0m[0;34m[0m[0;34m[0m[0m
[0m[1;32m      6[0m [0mglue[0m[0;34m([0m[0;34m"spline"[0m[0;34m,[0m [0mlogistic[0m[0;34m,[0m [0mdisplay[0m[0;34m=[0m[0;32mFalse[0m[0;34m)[0m[0;34m[0m[0;34m[0m[0m
[1;32m      7[0m [0;34m[0m[0m

[0;31mTypeError[0m: _repr_formula_latex_() missing 1 required positional argument: 'self'
TypeError: _repr_formula_latex_() missing 1 required positional argument: 'self'

