Traceback (most recent call last):
  File "/home/wsaelens/projects/probabilistic-cell/.venv/lib/python3.8/site-packages/jupyter_cache/executors/utils.py", line 51, in single_nb_execution
    executenb(
  File "/home/wsaelens/projects/probabilistic-cell/.venv/lib/python3.8/site-packages/nbclient/client.py", line 1117, in execute
    return NotebookClient(nb=nb, resources=resources, km=km, **kwargs).execute()
  File "/home/wsaelens/projects/probabilistic-cell/.venv/lib/python3.8/site-packages/nbclient/util.py", line 78, in wrapped
    return just_run(coro(*args, **kwargs))
  File "/home/wsaelens/projects/probabilistic-cell/.venv/lib/python3.8/site-packages/nbclient/util.py", line 57, in just_run
    return loop.run_until_complete(coro)
  File "/usr/lib/python3.8/asyncio/base_events.py", line 616, in run_until_complete
    return future.result()
  File "/home/wsaelens/projects/probabilistic-cell/.venv/lib/python3.8/site-packages/nbclient/client.py", line 558, in async_execute
    await self.async_execute_cell(
  File "/home/wsaelens/projects/probabilistic-cell/.venv/lib/python3.8/site-packages/nbclient/client.py", line 862, in async_execute_cell
    self._check_raise_for_error(cell, exec_reply)
  File "/home/wsaelens/projects/probabilistic-cell/.venv/lib/python3.8/site-packages/nbclient/client.py", line 765, in _check_raise_for_error
    raise CellExecutionError.from_cell_and_msg(cell, exec_reply_content)
nbclient.exceptions.CellExecutionError: An error occurred while executing the following cell:
------------------
dataset.create(force = False)
------------------

[0;31m---------------------------------------------------------------------------[0m
[0;31mTypeError[0m                                 Traceback (most recent call last)
[0;32m/tmp/ipykernel_2624590/555429015.py[0m in [0;36m<module>[0;34m[0m
[0;32m----> 1[0;31m [0mdataset[0m[0;34m.[0m[0mcreate[0m[0;34m([0m[0mforce[0m [0;34m=[0m [0;32mFalse[0m[0;34m)[0m[0;34m[0m[0;34m[0m[0m
[0m
[0;32m~/projects/probabilistic-cell/laflow/src/laflow/step.py[0m in [0;36m__call__[0;34m(self, force, skip)[0m
[1;32m    129[0m         [0;32melse[0m[0;34m:[0m[0;34m[0m[0;34m[0m[0m
[1;32m    130[0m             [0mlog[0m[0;34m.[0m[0minfo[0m[0;34m([0m[0;34m"▶️ | "[0m [0;34m+[0m [0mself[0m[0;34m.[0m[0m_format_step[0m[0;34m([0m[0;34m)[0m[0;34m)[0m[0;34m[0m[0;34m[0m[0m
[0;32m--> 131[0;31m             [0mself[0m[0;34m.[0m[0m_run[0m[0;34m([0m[0minputs[0m[0;34m,[0m [0moutputs[0m[0;34m)[0m[0;34m[0m[0;34m[0m[0m
[0m[1;32m    132[0m             [0mlog[0m[0;34m.[0m[0minfo[0m[0;34m([0m[0;34m"✅ | "[0m [0;34m+[0m [0mself[0m[0;34m.[0m[0m_format_step[0m[0;34m([0m[0;34m)[0m[0;34m)[0m[0;34m[0m[0;34m[0m[0m
[1;32m    133[0m [0;34m[0m[0m

[0;32m~/projects/probabilistic-cell/laflow/src/laflow/step.py[0m in [0;36m_run[0;34m(self, inputs, outputs)[0m
[1;32m    155[0m [0;34m[0m[0m
[1;32m    156[0m     [0;32mdef[0m [0m_run[0m[0;34m([0m[0mself[0m[0;34m,[0m [0minputs[0m[0;34m,[0m [0moutputs[0m[0;34m)[0m[0;34m:[0m[0;34m[0m[0;34m[0m[0m
[0;32m--> 157[0;31m         self.func(
[0m[1;32m    158[0m             [0mself[0m[0;34m=[0m[0mself[0m[0;34m.[0m[0minstance[0m[0;34m,[0m[0;34m[0m[0;34m[0m[0m
[1;32m    159[0m             [0;34m**[0m[0;34m{[0m[0minput_id[0m [0;34m+[0m [0;34m"_"[0m[0;34m:[0m [0minput[0m [0;32mfor[0m [0minput_id[0m[0;34m,[0m [0minput[0m [0;32min[0m [0minputs[0m[0;34m.[0m[0mitems[0m[0;34m([0m[0;34m)[0m[0;34m}[0m[0;34m,[0m[0;34m[0m[0;34m[0m[0m

[0;31mTypeError[0m: create() got an unexpected keyword argument 'data_'
TypeError: create() got an unexpected keyword argument 'data_'

