Traceback (most recent call last):
  File "/home/wsaelens/projects/probabilistic-cell/.venv/lib/python3.8/site-packages/jupyter_cache/executors/utils.py", line 51, in single_nb_execution
    executenb(
  File "/home/wsaelens/projects/probabilistic-cell/.venv/lib/python3.8/site-packages/nbclient/client.py", line 1117, in execute
    return NotebookClient(nb=nb, resources=resources, km=km, **kwargs).execute()
  File "/home/wsaelens/projects/probabilistic-cell/.venv/lib/python3.8/site-packages/nbclient/util.py", line 78, in wrapped
    return just_run(coro(*args, **kwargs))
  File "/home/wsaelens/projects/probabilistic-cell/.venv/lib/python3.8/site-packages/nbclient/util.py", line 57, in just_run
    return loop.run_until_complete(coro)
  File "/usr/lib/python3.8/asyncio/base_events.py", line 616, in run_until_complete
    return future.result()
  File "/home/wsaelens/projects/probabilistic-cell/.venv/lib/python3.8/site-packages/nbclient/client.py", line 558, in async_execute
    await self.async_execute_cell(
  File "/home/wsaelens/projects/probabilistic-cell/.venv/lib/python3.8/site-packages/nbclient/client.py", line 862, in async_execute_cell
    self._check_raise_for_error(cell, exec_reply)
  File "/home/wsaelens/projects/probabilistic-cell/.venv/lib/python3.8/site-packages/nbclient/client.py", line 765, in _check_raise_for_error
    raise CellExecutionError.from_cell_and_msg(cell, exec_reply_content)
nbclient.exceptions.CellExecutionError: An error occurred while executing the following cell:
------------------
model_gs = la.Model(dist, label = "ground truth", symbol = "gs")
model_gs.plot()
------------------

[0;31m---------------------------------------------------------------------------[0m
[0;31mAssertionError[0m                            Traceback (most recent call last)
[0;32m/tmp/ipykernel_412221/961674877.py[0m in [0;36m<module>[0;34m[0m
[0;32m----> 1[0;31m [0mmodel_gs[0m [0;34m=[0m [0mla[0m[0;34m.[0m[0mModel[0m[0;34m([0m[0mdist[0m[0;34m,[0m [0mlabel[0m [0;34m=[0m [0;34m"ground truth"[0m[0;34m,[0m [0msymbol[0m [0;34m=[0m [0;34m"gs"[0m[0;34m)[0m[0;34m[0m[0;34m[0m[0m
[0m[1;32m      2[0m [0mmodel_gs[0m[0;34m.[0m[0mplot[0m[0;34m([0m[0;34m)[0m[0;34m[0m[0;34m[0m[0m

[0;32m~/projects/probabilistic-cell/latenta/src/latenta/variables/model.py[0m in [0;36m__init__[0;34m(self, label, symbol, description, *args, **kwargs)[0m
[1;32m     19[0m         [0mself[0m[0;34m.[0m[0mcomponent_ids[0m [0;34m=[0m [0mset[0m[0;34m([0m[0;34m)[0m[0;34m[0m[0;34m[0m[0m
[1;32m     20[0m         [0;32mfor[0m [0mcomponent[0m [0;32min[0m [0margs[0m[0;34m:[0m[0;34m[0m[0;34m[0m[0m
[0;32m---> 21[0;31m             [0;32massert[0m [0mcomponent[0m[0;34m.[0m[0mlabelling[0m[0;34m.[0m[0mraw_label[0m [0;32mis[0m [0;32mnot[0m [0;32mNone[0m[0;34m[0m[0;34m[0m[0m
[0m[1;32m     22[0m [0;34m[0m[0m
[1;32m     23[0m             assert (

[0;31mAssertionError[0m: 
AssertionError: 

