Traceback (most recent call last):
  File "/home/wsaelens/projects/probabilistic-cell/.venv/lib/python3.8/site-packages/jupyter_cache/executors/utils.py", line 51, in single_nb_execution
    executenb(
  File "/home/wsaelens/projects/probabilistic-cell/.venv/lib/python3.8/site-packages/nbclient/client.py", line 1112, in execute
    return NotebookClient(nb=nb, resources=resources, km=km, **kwargs).execute()
  File "/home/wsaelens/projects/probabilistic-cell/.venv/lib/python3.8/site-packages/nbclient/util.py", line 74, in wrapped
    return just_run(coro(*args, **kwargs))
  File "/home/wsaelens/projects/probabilistic-cell/.venv/lib/python3.8/site-packages/nbclient/util.py", line 53, in just_run
    return loop.run_until_complete(coro)
  File "/usr/lib/python3.8/asyncio/base_events.py", line 616, in run_until_complete
    return future.result()
  File "/home/wsaelens/projects/probabilistic-cell/.venv/lib/python3.8/site-packages/nbclient/client.py", line 553, in async_execute
    await self.async_execute_cell(
  File "/home/wsaelens/projects/probabilistic-cell/.venv/lib/python3.8/site-packages/nbclient/client.py", line 857, in async_execute_cell
    self._check_raise_for_error(cell, exec_reply)
  File "/home/wsaelens/projects/probabilistic-cell/.venv/lib/python3.8/site-packages/nbclient/client.py", line 760, in _check_raise_for_error
    raise CellExecutionError.from_cell_and_msg(cell, exec_reply_content)
nbclient.exceptions.CellExecutionError: An error occurred while executing the following cell:
------------------
x = torch.tensor(5.)
for distribution_id in distributions_dim.coords:
    w = pd.Series(0., index = distributions_dim.index)
    w.loc[distribution_id] = 1.
    w = la.Fixed(w)
    
    mixture = la.distributions.Mixture(distributions = distributions_gs, weight=w, label="mixture")
    mixture.run_recursive()
    
    assert mixture.log_prob(x) == getattr(mixture, distribution_id).log_prob(x), distribution_id
------------------

[0;31m---------------------------------------------------------------------------[0m
[0;31mNameError[0m                                 Traceback (most recent call last)
[0;32m/tmp/ipykernel_2963672/1058910777.py[0m in [0;36m<module>[0;34m[0m
[0;32m----> 1[0;31m [0mx[0m [0;34m=[0m [0mtorch[0m[0;34m.[0m[0mtensor[0m[0;34m([0m[0;36m5.[0m[0;34m)[0m[0;34m[0m[0;34m[0m[0m
[0m[1;32m      2[0m [0;32mfor[0m [0mdistribution_id[0m [0;32min[0m [0mdistributions_dim[0m[0;34m.[0m[0mcoords[0m[0;34m:[0m[0;34m[0m[0;34m[0m[0m
[1;32m      3[0m     [0mw[0m [0;34m=[0m [0mpd[0m[0;34m.[0m[0mSeries[0m[0;34m([0m[0;36m0.[0m[0;34m,[0m [0mindex[0m [0;34m=[0m [0mdistributions_dim[0m[0;34m.[0m[0mindex[0m[0;34m)[0m[0;34m[0m[0;34m[0m[0m
[1;32m      4[0m     [0mw[0m[0;34m.[0m[0mloc[0m[0;34m[[0m[0mdistribution_id[0m[0;34m][0m [0;34m=[0m [0;36m1.[0m[0;34m[0m[0;34m[0m[0m
[1;32m      5[0m     [0mw[0m [0;34m=[0m [0mla[0m[0;34m.[0m[0mFixed[0m[0;34m([0m[0mw[0m[0;34m)[0m[0;34m[0m[0;34m[0m[0m

[0;31mNameError[0m: name 'torch' is not defined
NameError: name 'torch' is not defined

